<?xml version="1.0" encoding="UTF-8"?>
<testng-results retried="4" ignored="0" total="5" passed="0" failed="1" skipped="0">
  <reporter-output>
    <line>
      <![CDATA[Screenshot of Failed Testscript is stored in Screenshot Folder]]>
    </line>
  </reporter-output>
  <suite started-at="2022-11-08T12:27:13 IST" name="Default suite" finished-at="2022-11-08T12:28:43 IST" duration-ms="90409">
    <groups>
    </groups>
    <test started-at="2022-11-08T12:27:13 IST" name="Default test" finished-at="2022-11-08T12:28:43 IST" duration-ms="90409">
      <class name="com.Vtiger.PomScripts.Tc_001_CreateContact_Test">
        <test-method is-config="true" signature="startconnection()[pri:0, instance:com.Vtiger.PomScripts.Tc_001_CreateContact_Test@3c77d488]" started-at="2022-11-08T12:27:13 IST" name="startconnection" finished-at="2022-11-08T12:27:13 IST" duration-ms="12" status="PASS">
          <reporter-output>
          </reporter-output>
        </test-method> <!-- startconnection -->
        <test-method is-config="true" signature="launchbrowser()[pri:0, instance:com.Vtiger.PomScripts.Tc_001_CreateContact_Test@3c77d488]" started-at="2022-11-08T12:27:13 IST" name="launchbrowser" finished-at="2022-11-08T12:27:19 IST" duration-ms="5705" status="PASS">
          <reporter-output>
          </reporter-output>
        </test-method> <!-- launchbrowser -->
        <test-method is-config="true" signature="logindetails()[pri:0, instance:com.Vtiger.PomScripts.Tc_001_CreateContact_Test@3c77d488]" started-at="2022-11-08T12:27:19 IST" name="logindetails" finished-at="2022-11-08T12:27:22 IST" duration-ms="3597" status="PASS">
          <reporter-output>
          </reporter-output>
        </test-method> <!-- logindetails -->
        <test-method retried="true" signature="TC001_CreateContact()[pri:0, instance:com.Vtiger.PomScripts.Tc_001_CreateContact_Test@3c77d488]" started-at="2022-11-08T12:27:22 IST" name="TC001_CreateContact" finished-at="2022-11-08T12:27:36 IST" duration-ms="13806" status="SKIP">
          <exception class="java.lang.AssertionError">
            <message>
              <![CDATA[expected [false] but found [true]]]>
            </message>
            <full-stacktrace>
              <![CDATA[java.lang.AssertionError: expected [false] but found [true]
at org.testng.Assert.fail(Assert.java:99)
at org.testng.Assert.failNotEquals(Assert.java:1037)
at org.testng.Assert.assertFalse(Assert.java:67)
at org.testng.Assert.assertFalse(Assert.java:77)
at com.Vtiger.PomScripts.Tc_001_CreateContact_Test.TC001_CreateContact(Tc_001_CreateContact_Test.java:67)
at java.base/jdk.internal.reflect.NativeMethodAccessorImpl.invoke0(Native Method)
at java.base/jdk.internal.reflect.NativeMethodAccessorImpl.invoke(NativeMethodAccessorImpl.java:77)
at java.base/jdk.internal.reflect.DelegatingMethodAccessorImpl.invoke(DelegatingMethodAccessorImpl.java:43)
at java.base/java.lang.reflect.Method.invoke(Method.java:568)
at org.testng.internal.MethodInvocationHelper.invokeMethod(MethodInvocationHelper.java:133)
at org.testng.internal.TestInvoker.invokeMethod(TestInvoker.java:598)
at org.testng.internal.TestInvoker.invokeTestMethod(TestInvoker.java:173)
at org.testng.internal.MethodRunner.runInSequence(MethodRunner.java:46)
at org.testng.internal.TestInvoker$MethodInvocationAgent.invoke(TestInvoker.java:824)
at org.testng.internal.TestInvoker.invokeTestMethods(TestInvoker.java:146)
at org.testng.internal.TestMethodWorker.invokeTestMethods(TestMethodWorker.java:146)
at org.testng.internal.TestMethodWorker.run(TestMethodWorker.java:128)
at java.base/java.util.ArrayList.forEach(ArrayList.java:1511)
at org.testng.TestRunner.privateRun(TestRunner.java:794)
at org.testng.TestRunner.run(TestRunner.java:596)
at org.testng.SuiteRunner.runTest(SuiteRunner.java:377)
at org.testng.SuiteRunner.runSequentially(SuiteRunner.java:371)
at org.testng.SuiteRunner.privateRun(SuiteRunner.java:332)
at org.testng.SuiteRunner.run(SuiteRunner.java:276)
at org.testng.SuiteRunnerWorker.runSuite(SuiteRunnerWorker.java:53)
at org.testng.SuiteRunnerWorker.run(SuiteRunnerWorker.java:96)
at org.testng.TestNG.runSuitesSequentially(TestNG.java:1212)
at org.testng.TestNG.runSuitesLocally(TestNG.java:1134)
at org.testng.TestNG.runSuites(TestNG.java:1063)
at org.testng.TestNG.run(TestNG.java:1031)
at org.testng.remote.AbstractRemoteTestNG.run(AbstractRemoteTestNG.java:115)
at org.testng.remote.RemoteTestNG.initAndRun(RemoteTestNG.java:251)
at org.testng.remote.RemoteTestNG.main(RemoteTestNG.java:77)
]]>
            </full-stacktrace>
          </exception> <!-- java.lang.AssertionError -->
          <reporter-output>
          </reporter-output>
        </test-method> <!-- TC001_CreateContact -->
        <test-method is-config="true" signature="logout()[pri:0, instance:com.Vtiger.PomScripts.Tc_001_CreateContact_Test@3c77d488]" started-at="2022-11-08T12:27:36 IST" name="logout" finished-at="2022-11-08T12:27:38 IST" duration-ms="1571" status="PASS">
          <reporter-output>
          </reporter-output>
        </test-method> <!-- logout -->
        <test-method is-config="true" signature="logindetails()[pri:0, instance:com.Vtiger.PomScripts.Tc_001_CreateContact_Test@3c77d488]" started-at="2022-11-08T12:27:38 IST" name="logindetails" finished-at="2022-11-08T12:27:41 IST" duration-ms="2800" status="PASS">
          <reporter-output>
          </reporter-output>
        </test-method> <!-- logindetails -->
        <test-method retried="true" signature="TC001_CreateContact()[pri:0, instance:com.Vtiger.PomScripts.Tc_001_CreateContact_Test@3c77d488]" started-at="2022-11-08T12:27:41 IST" name="TC001_CreateContact" finished-at="2022-11-08T12:27:53 IST" duration-ms="12921" status="SKIP">
          <exception class="java.lang.AssertionError">
            <message>
              <![CDATA[expected [false] but found [true]]]>
            </message>
            <full-stacktrace>
              <![CDATA[java.lang.AssertionError: expected [false] but found [true]
at org.testng.Assert.fail(Assert.java:99)
at org.testng.Assert.failNotEquals(Assert.java:1037)
at org.testng.Assert.assertFalse(Assert.java:67)
at org.testng.Assert.assertFalse(Assert.java:77)
at com.Vtiger.PomScripts.Tc_001_CreateContact_Test.TC001_CreateContact(Tc_001_CreateContact_Test.java:67)
at java.base/jdk.internal.reflect.NativeMethodAccessorImpl.invoke0(Native Method)
at java.base/jdk.internal.reflect.NativeMethodAccessorImpl.invoke(NativeMethodAccessorImpl.java:77)
at java.base/jdk.internal.reflect.DelegatingMethodAccessorImpl.invoke(DelegatingMethodAccessorImpl.java:43)
at java.base/java.lang.reflect.Method.invoke(Method.java:568)
at org.testng.internal.MethodInvocationHelper.invokeMethod(MethodInvocationHelper.java:133)
at org.testng.internal.TestInvoker.invokeMethod(TestInvoker.java:598)
at org.testng.internal.TestInvoker.retryFailed(TestInvoker.java:213)
at org.testng.internal.MethodRunner.runInSequence(MethodRunner.java:58)
at org.testng.internal.TestInvoker$MethodInvocationAgent.invoke(TestInvoker.java:824)
at org.testng.internal.TestInvoker.invokeTestMethods(TestInvoker.java:146)
at org.testng.internal.TestMethodWorker.invokeTestMethods(TestMethodWorker.java:146)
at org.testng.internal.TestMethodWorker.run(TestMethodWorker.java:128)
at java.base/java.util.ArrayList.forEach(ArrayList.java:1511)
at org.testng.TestRunner.privateRun(TestRunner.java:794)
at org.testng.TestRunner.run(TestRunner.java:596)
at org.testng.SuiteRunner.runTest(SuiteRunner.java:377)
at org.testng.SuiteRunner.runSequentially(SuiteRunner.java:371)
at org.testng.SuiteRunner.privateRun(SuiteRunner.java:332)
at org.testng.SuiteRunner.run(SuiteRunner.java:276)
at org.testng.SuiteRunnerWorker.runSuite(SuiteRunnerWorker.java:53)
at org.testng.SuiteRunnerWorker.run(SuiteRunnerWorker.java:96)
at org.testng.TestNG.runSuitesSequentially(TestNG.java:1212)
at org.testng.TestNG.runSuitesLocally(TestNG.java:1134)
at org.testng.TestNG.runSuites(TestNG.java:1063)
at org.testng.TestNG.run(TestNG.java:1031)
at org.testng.remote.AbstractRemoteTestNG.run(AbstractRemoteTestNG.java:115)
at org.testng.remote.RemoteTestNG.initAndRun(RemoteTestNG.java:251)
at org.testng.remote.RemoteTestNG.main(RemoteTestNG.java:77)
]]>
            </full-stacktrace>
          </exception> <!-- java.lang.AssertionError -->
          <reporter-output>
          </reporter-output>
        </test-method> <!-- TC001_CreateContact -->
        <test-method is-config="true" signature="logout()[pri:0, instance:com.Vtiger.PomScripts.Tc_001_CreateContact_Test@3c77d488]" started-at="2022-11-08T12:27:53 IST" name="logout" finished-at="2022-11-08T12:27:55 IST" duration-ms="1285" status="PASS">
          <reporter-output>
          </reporter-output>
        </test-method> <!-- logout -->
        <test-method is-config="true" signature="logindetails()[pri:0, instance:com.Vtiger.PomScripts.Tc_001_CreateContact_Test@3c77d488]" started-at="2022-11-08T12:27:55 IST" name="logindetails" finished-at="2022-11-08T12:27:57 IST" duration-ms="2436" status="PASS">
          <reporter-output>
          </reporter-output>
        </test-method> <!-- logindetails -->
        <test-method retried="true" signature="TC001_CreateContact()[pri:0, instance:com.Vtiger.PomScripts.Tc_001_CreateContact_Test@3c77d488]" started-at="2022-11-08T12:27:57 IST" name="TC001_CreateContact" finished-at="2022-11-08T12:28:09 IST" duration-ms="12193" status="SKIP">
          <exception class="java.lang.AssertionError">
            <message>
              <![CDATA[expected [false] but found [true]]]>
            </message>
            <full-stacktrace>
              <![CDATA[java.lang.AssertionError: expected [false] but found [true]
at org.testng.Assert.fail(Assert.java:99)
at org.testng.Assert.failNotEquals(Assert.java:1037)
at org.testng.Assert.assertFalse(Assert.java:67)
at org.testng.Assert.assertFalse(Assert.java:77)
at com.Vtiger.PomScripts.Tc_001_CreateContact_Test.TC001_CreateContact(Tc_001_CreateContact_Test.java:67)
at java.base/jdk.internal.reflect.NativeMethodAccessorImpl.invoke0(Native Method)
at java.base/jdk.internal.reflect.NativeMethodAccessorImpl.invoke(NativeMethodAccessorImpl.java:77)
at java.base/jdk.internal.reflect.DelegatingMethodAccessorImpl.invoke(DelegatingMethodAccessorImpl.java:43)
at java.base/java.lang.reflect.Method.invoke(Method.java:568)
at org.testng.internal.MethodInvocationHelper.invokeMethod(MethodInvocationHelper.java:133)
at org.testng.internal.TestInvoker.invokeMethod(TestInvoker.java:598)
at org.testng.internal.TestInvoker.retryFailed(TestInvoker.java:213)
at org.testng.internal.MethodRunner.runInSequence(MethodRunner.java:58)
at org.testng.internal.TestInvoker$MethodInvocationAgent.invoke(TestInvoker.java:824)
at org.testng.internal.TestInvoker.invokeTestMethods(TestInvoker.java:146)
at org.testng.internal.TestMethodWorker.invokeTestMethods(TestMethodWorker.java:146)
at org.testng.internal.TestMethodWorker.run(TestMethodWorker.java:128)
at java.base/java.util.ArrayList.forEach(ArrayList.java:1511)
at org.testng.TestRunner.privateRun(TestRunner.java:794)
at org.testng.TestRunner.run(TestRunner.java:596)
at org.testng.SuiteRunner.runTest(SuiteRunner.java:377)
at org.testng.SuiteRunner.runSequentially(SuiteRunner.java:371)
at org.testng.SuiteRunner.privateRun(SuiteRunner.java:332)
at org.testng.SuiteRunner.run(SuiteRunner.java:276)
at org.testng.SuiteRunnerWorker.runSuite(SuiteRunnerWorker.java:53)
at org.testng.SuiteRunnerWorker.run(SuiteRunnerWorker.java:96)
at org.testng.TestNG.runSuitesSequentially(TestNG.java:1212)
at org.testng.TestNG.runSuitesLocally(TestNG.java:1134)
at org.testng.TestNG.runSuites(TestNG.java:1063)
at org.testng.TestNG.run(TestNG.java:1031)
at org.testng.remote.AbstractRemoteTestNG.run(AbstractRemoteTestNG.java:115)
at org.testng.remote.RemoteTestNG.initAndRun(RemoteTestNG.java:251)
at org.testng.remote.RemoteTestNG.main(RemoteTestNG.java:77)
]]>
            </full-stacktrace>
          </exception> <!-- java.lang.AssertionError -->
          <reporter-output>
          </reporter-output>
        </test-method> <!-- TC001_CreateContact -->
        <test-method is-config="true" signature="logout()[pri:0, instance:com.Vtiger.PomScripts.Tc_001_CreateContact_Test@3c77d488]" started-at="2022-11-08T12:28:09 IST" name="logout" finished-at="2022-11-08T12:28:11 IST" duration-ms="1329" status="PASS">
          <reporter-output>
          </reporter-output>
        </test-method> <!-- logout -->
        <test-method is-config="true" signature="logindetails()[pri:0, instance:com.Vtiger.PomScripts.Tc_001_CreateContact_Test@3c77d488]" started-at="2022-11-08T12:28:11 IST" name="logindetails" finished-at="2022-11-08T12:28:13 IST" duration-ms="2586" status="PASS">
          <reporter-output>
          </reporter-output>
        </test-method> <!-- logindetails -->
        <test-method retried="true" signature="TC001_CreateContact()[pri:0, instance:com.Vtiger.PomScripts.Tc_001_CreateContact_Test@3c77d488]" started-at="2022-11-08T12:28:13 IST" name="TC001_CreateContact" finished-at="2022-11-08T12:28:25 IST" duration-ms="11644" status="SKIP">
          <exception class="java.lang.AssertionError">
            <message>
              <![CDATA[expected [false] but found [true]]]>
            </message>
            <full-stacktrace>
              <![CDATA[java.lang.AssertionError: expected [false] but found [true]
at org.testng.Assert.fail(Assert.java:99)
at org.testng.Assert.failNotEquals(Assert.java:1037)
at org.testng.Assert.assertFalse(Assert.java:67)
at org.testng.Assert.assertFalse(Assert.java:77)
at com.Vtiger.PomScripts.Tc_001_CreateContact_Test.TC001_CreateContact(Tc_001_CreateContact_Test.java:67)
at java.base/jdk.internal.reflect.NativeMethodAccessorImpl.invoke0(Native Method)
at java.base/jdk.internal.reflect.NativeMethodAccessorImpl.invoke(NativeMethodAccessorImpl.java:77)
at java.base/jdk.internal.reflect.DelegatingMethodAccessorImpl.invoke(DelegatingMethodAccessorImpl.java:43)
at java.base/java.lang.reflect.Method.invoke(Method.java:568)
at org.testng.internal.MethodInvocationHelper.invokeMethod(MethodInvocationHelper.java:133)
at org.testng.internal.TestInvoker.invokeMethod(TestInvoker.java:598)
at org.testng.internal.TestInvoker.retryFailed(TestInvoker.java:213)
at org.testng.internal.MethodRunner.runInSequence(MethodRunner.java:58)
at org.testng.internal.TestInvoker$MethodInvocationAgent.invoke(TestInvoker.java:824)
at org.testng.internal.TestInvoker.invokeTestMethods(TestInvoker.java:146)
at org.testng.internal.TestMethodWorker.invokeTestMethods(TestMethodWorker.java:146)
at org.testng.internal.TestMethodWorker.run(TestMethodWorker.java:128)
at java.base/java.util.ArrayList.forEach(ArrayList.java:1511)
at org.testng.TestRunner.privateRun(TestRunner.java:794)
at org.testng.TestRunner.run(TestRunner.java:596)
at org.testng.SuiteRunner.runTest(SuiteRunner.java:377)
at org.testng.SuiteRunner.runSequentially(SuiteRunner.java:371)
at org.testng.SuiteRunner.privateRun(SuiteRunner.java:332)
at org.testng.SuiteRunner.run(SuiteRunner.java:276)
at org.testng.SuiteRunnerWorker.runSuite(SuiteRunnerWorker.java:53)
at org.testng.SuiteRunnerWorker.run(SuiteRunnerWorker.java:96)
at org.testng.TestNG.runSuitesSequentially(TestNG.java:1212)
at org.testng.TestNG.runSuitesLocally(TestNG.java:1134)
at org.testng.TestNG.runSuites(TestNG.java:1063)
at org.testng.TestNG.run(TestNG.java:1031)
at org.testng.remote.AbstractRemoteTestNG.run(AbstractRemoteTestNG.java:115)
at org.testng.remote.RemoteTestNG.initAndRun(RemoteTestNG.java:251)
at org.testng.remote.RemoteTestNG.main(RemoteTestNG.java:77)
]]>
            </full-stacktrace>
          </exception> <!-- java.lang.AssertionError -->
          <reporter-output>
          </reporter-output>
        </test-method> <!-- TC001_CreateContact -->
        <test-method is-config="true" signature="logout()[pri:0, instance:com.Vtiger.PomScripts.Tc_001_CreateContact_Test@3c77d488]" started-at="2022-11-08T12:28:25 IST" name="logout" finished-at="2022-11-08T12:28:26 IST" duration-ms="1157" status="PASS">
          <reporter-output>
          </reporter-output>
        </test-method> <!-- logout -->
        <test-method is-config="true" signature="logindetails()[pri:0, instance:com.Vtiger.PomScripts.Tc_001_CreateContact_Test@3c77d488]" started-at="2022-11-08T12:28:26 IST" name="logindetails" finished-at="2022-11-08T12:28:29 IST" duration-ms="2436" status="PASS">
          <reporter-output>
          </reporter-output>
        </test-method> <!-- logindetails -->
        <test-method signature="TC001_CreateContact()[pri:0, instance:com.Vtiger.PomScripts.Tc_001_CreateContact_Test@3c77d488]" started-at="2022-11-08T12:28:29 IST" name="TC001_CreateContact" finished-at="2022-11-08T12:28:41 IST" duration-ms="12253" status="FAIL">
          <exception class="java.lang.AssertionError">
            <message>
              <![CDATA[expected [false] but found [true]]]>
            </message>
            <full-stacktrace>
              <![CDATA[java.lang.AssertionError: expected [false] but found [true]
at org.testng.Assert.fail(Assert.java:99)
at org.testng.Assert.failNotEquals(Assert.java:1037)
at org.testng.Assert.assertFalse(Assert.java:67)
at org.testng.Assert.assertFalse(Assert.java:77)
at com.Vtiger.PomScripts.Tc_001_CreateContact_Test.TC001_CreateContact(Tc_001_CreateContact_Test.java:67)
at java.base/jdk.internal.reflect.NativeMethodAccessorImpl.invoke0(Native Method)
at java.base/jdk.internal.reflect.NativeMethodAccessorImpl.invoke(NativeMethodAccessorImpl.java:77)
at java.base/jdk.internal.reflect.DelegatingMethodAccessorImpl.invoke(DelegatingMethodAccessorImpl.java:43)
at java.base/java.lang.reflect.Method.invoke(Method.java:568)
at org.testng.internal.MethodInvocationHelper.invokeMethod(MethodInvocationHelper.java:133)
at org.testng.internal.TestInvoker.invokeMethod(TestInvoker.java:598)
at org.testng.internal.TestInvoker.retryFailed(TestInvoker.java:213)
at org.testng.internal.MethodRunner.runInSequence(MethodRunner.java:58)
at org.testng.internal.TestInvoker$MethodInvocationAgent.invoke(TestInvoker.java:824)
at org.testng.internal.TestInvoker.invokeTestMethods(TestInvoker.java:146)
at org.testng.internal.TestMethodWorker.invokeTestMethods(TestMethodWorker.java:146)
at org.testng.internal.TestMethodWorker.run(TestMethodWorker.java:128)
at java.base/java.util.ArrayList.forEach(ArrayList.java:1511)
at org.testng.TestRunner.privateRun(TestRunner.java:794)
at org.testng.TestRunner.run(TestRunner.java:596)
at org.testng.SuiteRunner.runTest(SuiteRunner.java:377)
at org.testng.SuiteRunner.runSequentially(SuiteRunner.java:371)
at org.testng.SuiteRunner.privateRun(SuiteRunner.java:332)
at org.testng.SuiteRunner.run(SuiteRunner.java:276)
at org.testng.SuiteRunnerWorker.runSuite(SuiteRunnerWorker.java:53)
at org.testng.SuiteRunnerWorker.run(SuiteRunnerWorker.java:96)
at org.testng.TestNG.runSuitesSequentially(TestNG.java:1212)
at org.testng.TestNG.runSuitesLocally(TestNG.java:1134)
at org.testng.TestNG.runSuites(TestNG.java:1063)
at org.testng.TestNG.run(TestNG.java:1031)
at org.testng.remote.AbstractRemoteTestNG.run(AbstractRemoteTestNG.java:115)
at org.testng.remote.RemoteTestNG.initAndRun(RemoteTestNG.java:251)
at org.testng.remote.RemoteTestNG.main(RemoteTestNG.java:77)
]]>
            </full-stacktrace>
          </exception> <!-- java.lang.AssertionError -->
          <reporter-output>
            <line>
              <![CDATA[Screenshot of Failed Testscript is stored in Screenshot Folder]]>
            </line>
          </reporter-output>
        </test-method> <!-- TC001_CreateContact -->
        <test-method is-config="true" signature="logout()[pri:0, instance:com.Vtiger.PomScripts.Tc_001_CreateContact_Test@3c77d488]" started-at="2022-11-08T12:28:42 IST" name="logout" finished-at="2022-11-08T12:28:43 IST" duration-ms="1343" status="PASS">
          <reporter-output>
          </reporter-output>
        </test-method> <!-- logout -->
        <test-method is-config="true" signature="closebrowser()[pri:0, instance:com.Vtiger.PomScripts.Tc_001_CreateContact_Test@3c77d488]" started-at="2022-11-08T12:28:43 IST" name="closebrowser" finished-at="2022-11-08T12:28:43 IST" duration-ms="107" status="PASS">
          <reporter-output>
          </reporter-output>
        </test-method> <!-- closebrowser -->
        <test-method is-config="true" signature="closeconnection()[pri:0, instance:com.Vtiger.PomScripts.Tc_001_CreateContact_Test@3c77d488]" started-at="2022-11-08T12:28:44 IST" name="closeconnection" finished-at="2022-11-08T12:28:44 IST" duration-ms="1" status="PASS">
          <reporter-output>
          </reporter-output>
        </test-method> <!-- closeconnection -->
      </class> <!-- com.Vtiger.PomScripts.Tc_001_CreateContact_Test -->
    </test> <!-- Default test -->
  </suite> <!-- Default suite -->
</testng-results>
